<?xml version="1.0" encoding="utf-8"?>
<!-- This URDF was automatically created by SolidWorks to URDF Exporter! Originally created by Stephen Brawner (brawner@gmail.com)
     Commit Version: 1.6.0-4-g7f85cfe  Build Version: 1.6.7995.38578
     For more information, please see http://wiki.ros.org/sw_urdf_exporter -->
<robot
  name="hodor_10">
  <link
    name="base_link">
    <inertial>
      <origin
        xyz="2.98364334947454E-05 1.55038827031294E-05 -0.010200312130708"
        rpy="0 0 0" />
      <mass
        value="0.491514800427233" />
      <inertia
        ixx="0.00199220117509473"
        ixy="-1.19655263995672E-06"
        ixz="-3.05317721576714E-14"
        iyy="0.00198772980356383"
        iyz="3.24735841369864E-12"
        izz="0.00395532460374651" />
    </inertial>
    <visual>
      <origin
        xyz="0 0 0"
        rpy="0 0 0" />
      <geometry>
        <mesh
          filename="package://hodor_10/meshes/base_link.STL" />
      </geometry>
      <material
        name="">
        <color
          rgba="0.792156862745098 0.819607843137255 0.933333333333333 1" />
      </material>
    </visual>
    <collision>
      <origin
        xyz="0 0 0"
        rpy="0 0 0" />
      <geometry>
        <mesh
          filename="package://hodor_10/meshes/base_link.STL" />
      </geometry>
    </collision>
  </link>
  <link
    name="front_wheel">
    <inertial>
      <origin
        xyz="2.19962936753859E-15 -0.00949451387962603 2.0122792321331E-16"
        rpy="0 0 0" />
      <mass
        value="0.0378266477345021" />
      <inertia
        ixx="2.85081163385123E-06"
        ixy="-2.31743346875003E-22"
        ixz="-1.93572531702206E-21"
        iyy="5.19859045981001E-06"
        iyz="4.67374782417283E-23"
        izz="2.85081163385124E-06" />
    </inertial>
    <visual>
      <origin
        xyz="0 0 0"
        rpy="0 0 0" />
      <geometry>
        <mesh
          filename="package://hodor_10/meshes/front_wheel.STL" />
      </geometry>
      <material
        name="">
        <color
          rgba="0.752941176470588 0.752941176470588 0.752941176470588 1" />
      </material>
    </visual>
    <collision>
      <origin
        xyz="0 0 0"
        rpy="0 0 0" />
      <geometry>
        <mesh
          filename="package://hodor_10/meshes/front_wheel.STL" />
      </geometry>
    </collision>
  </link>
  <joint
    name="front_joint"
    type="continuous">
    <origin
      xyz="0.17483 0.000181 -0.0335"
      rpy="0 0 -1.5708" />
    <parent
      link="base_link" />
    <child
      link="front_wheel" />
    <axis
      xyz="0 -1 0" />
    <limit
      effort="5"
      velocity="5" />
  </joint>
  <link
    name="right_wheel">
    <inertial>
      <origin
        xyz="3.33066907387547E-16 -0.0095054861203738 3.35148575558719E-15"
        rpy="0 0 0" />
      <mass
        value="0.0378266477345021" />
      <inertia
        ixx="2.85081163385124E-06"
        ixy="7.19978005166155E-21"
        ixz="-4.92346401724693E-21"
        iyy="5.19859045981002E-06"
        iyz="1.00289847665109E-21"
        izz="2.85081163385124E-06" />
    </inertial>
    <visual>
      <origin
        xyz="0 0 0"
        rpy="0 0 0" />
      <geometry>
        <mesh
          filename="package://hodor_10/meshes/right_wheel.STL" />
      </geometry>
      <material
        name="">
        <color
          rgba="0.752941176470588 0.752941176470588 0.752941176470588 1" />
      </material>
    </visual>
    <collision>
      <origin
        xyz="0 0 0"
        rpy="0 0 0" />
      <geometry>
        <mesh
          filename="package://hodor_10/meshes/right_wheel.STL" />
      </geometry>
    </collision>
  </link>
  <joint
    name="right_joint"
    type="continuous">
    <origin
      xyz="-0.087275 -0.15154 -0.0335"
      rpy="0 0 2.618" />
    <parent
      link="base_link" />
    <child
      link="right_wheel" />
    <axis
      xyz="0 1 0" />
    <limit
      effort="5"
      velocity="5" />
  </joint>
  <link
    name="left_wheel">
    <inertial>
      <origin
        xyz="0.143302051635367 -0.257700948140946 8.12544476147536E-15"
        rpy="0 0 0" />
      <mass
        value="0.0378266477345021" />
      <inertia
        ixx="4.6116457533203E-06"
        ixy="-1.01661805287376E-06"
        ixz="-8.17147467487926E-22"
        iyy="3.43775634034092E-06"
        iyz="-3.68269909902125E-21"
        izz="2.85081163385121E-06" />
    </inertial>
    <visual>
      <origin
        xyz="0 0 0"
        rpy="0 0 0" />
      <geometry>
        <mesh
          filename="package://hodor_10/meshes/left_wheel.STL" />
      </geometry>
      <material
        name="">
        <color
          rgba="0.752941176470588 0.752941176470588 0.752941176470588 1" />
      </material>
    </visual>
    <collision>
      <origin
        xyz="0 0 0"
        rpy="0 0 0" />
      <geometry>
        <mesh
          filename="package://hodor_10/meshes/left_wheel.STL" />
      </geometry>
    </collision>
  </link>
  <joint
    name="left_joint"
    type="continuous">
    <origin
      xyz="-0.087275 -0.15154 -0.0335"
      rpy="0 0 2.618" />
    <parent
      link="base_link" />
    <child
      link="left_wheel" />
    <axis
      xyz="-0.86603 0.5 0" />
    <limit
      effort="5"
      velocity="5" />
  </joint>
  <gazebo>
    <plugin name="object_controller" filename="libgazebo_ros_planar_move.so">
      <commandTopic>cmd_vel</commandTopic>
      <odometryTopic>odom</odometryTopic>
      <odometryFrame>odom</odometryFrame>
      <odometryRate>20.0</odometryRate>
      <robotBaseFrame>base_link</robotBaseFrame>
    </plugin>
  </gazebo>
</robot>
